.....F...........
======================================================================
FAIL: test_eval_6 (__main__.TestCollatz)
----------------------------------------------------------------------
Traceback (most recent call last):
  File "./TestCollatz.py", line 92, in test_eval_6
    self.assert_(v == 11)
AssertionError: False is not true

----------------------------------------------------------------------
Ran 17 tests in 1.260s

FAILED (failures=1)
TestCollatz.py
